Workbook

Sheet Guide
A1: EXPORT INVOICE / 使い方
A4: 01 | B4: Headerに入力 | C4: 青いセルに請求書情報・取引先・出荷情報を入力します。帳票の文字は英語で入力してください。
A5: 02 | B5: Itemsに商品を入力 | C5: 3〜32行へ上から入力。SKUとHSコードは文字列です。K・M・N列は数式なので上書きしないでください。
A6: 03 | B6: 書類種類を選ぶ | C6: Header B3でCOMMERCIAL / PROFORMAを切替。Proformaの有効期限・宣言文も確認します。
A7: 04 | B7: 入力チェック | C7: Header B53とItems M列を確認。通貨の小数桁はHeader B7。運賃等は商品価格との二重加算を避けます。
A8: 05 | B8: 印刷するページ | C8: Header B49が必要枚数。Invoice_1から必要な枚数だけ印刷します。不要ページは印刷しません。
A9: 06 | B9: A4設定 | C9: 各InvoiceシートのA1:H37を選択 → 印刷 → 選択中のセル → A4・縦向き・幅に合わせる・余白「狭い」。プレビューで1ページを確認。
A10: 07 | B10: 発行前 | C10: 宛先・品目・価格・原産国・HS・税務番号・宣言等を確認し、Header B45をFINALへ。署名・日付を記入して発行します。
A11: 08 | B11: 商品数と長文 | C11: 最大30商品、1ページ10行。空行を挟むと空枠が残ります。商品説明は110文字目安。長い住所や備考は印刷プレビューで確認してください。
A12: 09 | B12: 重量・箱数 | C12: Headerの重量と箱数は出荷全体。Items H〜J列は任意の行合計重量で、帳票には出荷全体を表示します。重量単位を混在させないでください。
A13: 10 | B13: CSVとの接続 | C13: Header A2:B45をkey/value、Items A2:J32を商品CSVの基礎にできます。CSV自動取込やWebアプリ自体は未実装です。
A14: 11 | B14: Google Sheets | C14: 印刷設定は出力時に指定してください。金額は小数2〜3桁表示、単価は4桁表示です。丸めはHeader B7に従います。JPYの.00表示はゼロ小数です。単価は小数4桁以内で入力。
A15: 12 | B15: テンプレートを保存 | C15: 毎回このブックをコピーして使用。計算セルと印刷シートは編集しないでください。31商品以上はアプリ実装時にページ生成を拡張します。
A16: 13 | B16: 確認の範囲 | C16: 基本チェックは入力漏れの補助です。提出先の必要項目・HS分類・宣言文の適合性までは判定しません。
A19: このブックは空の入力テンプレートです。取引内容を入力すると帳票へ自動反映します。実在企業や架空の売買情報は初期入力していません。

Sheet Header
A1: INVOICE SETTINGS / 請求書・出荷情報
A2: field_key | B2: value（入力） | C2: 入力ガイド
A3: invoice_type | B3: PROFORMA | C3: COMMERCIAL / PROFORMA を選択
A4: invoice_number | C4: 請求書番号。文字列として入力
A5: invoice_date | C5: 発行日：YYYY-MM-DD（文字列）
A6: currency | B6: USD | C6: USD / JPY / EUR / GBP。その他の通貨もコード入力可
A7: currency_decimals | B7: 2 | C7: 通貨の小数桁：JPY=0、USD/EUR/GBP=2。通貨変更時に確認
A8: payment_terms | C8: 例：100% payment before shipment
A9: incoterms | C9: 例：FCA Tokyo, Incoterms 2020（指定地を含める）
A10: purpose_of_export | C10: 例：Sale / Sample / Return for repair
A11: po_number | C11: 注文番号（任意）
A12: valid_until | C12: Proformaの有効期限：YYYY-MM-DD
A13: shipping_date | C13: 出荷日／予定出荷日：YYYY-MM-DD
A14: shipping_method | C14: 例：Air / Sea / Courier
A15: carrier_tracking | C15: 運送会社とAWB・追跡番号（未確定なら空欄）
A16: export_country | B16: Japan | C16: 輸出国
A17: destination_country | C17: 最終仕向国
A18: exporter_company | C18: 輸出者の法人名
A19: exporter_address | C19: 番地・市区町村・都道府県・郵便番号・国（英語）
A20: exporter_contact | C20: 担当者・電話・メール
A21: exporter_tax_id | C21: 登録番号等。必要に応じ入力
A22: buyer_company | C22: 買主の法人名
A23: buyer_address | C23: 買主の住所・郵便番号・国（英語）
A24: buyer_contact | C24: 買主の担当者・電話・メール
A25: buyer_tax_id | C25: 買主の税務番号等
A26: ship_to_company | C26: 配送先の法人名。空欄の場合は買主と同じ
A27: ship_to_address | C27: 配送先が異なる場合の住所・郵便番号・国
A28: ship_to_contact | C28: 配送先の担当者・電話・メール
... A35: gross_weight | C35: 梱包込みの総重量。数値
A36: weight_unit | B36: kg | C36: kg / lb
A37: freight_charge | B37: 0 | C37: 商品価格に含まれない追加運賃のみ
A38: insurance_charge | B38: 0 | C38: 商品価格に含まれない追加保険料のみ
A39: other_charge | B39: 0 | C39: その他の追加費用。値引きはこの版では扱わない
A40: remarks | C40: 備考。100文字目安。長文は別紙
A41: signatory_name | C41: 署名者名
A42: signatory_title | C42: 署名者の役職
A43: commercial_declaration | C43: Commercial用宣言。取引・仕向国に応じて入力
A44: proforma_declaration | B44: Proforma invoice for quotation purposes. | C44: Proforma用宣言。用途に応じて書き換える
A45: document_status | B45: DRAFT | C45: 確認後にFINALへ。チェック結果だけで通関適合は保証しない
A47: AUTOMATIC CHECKS / 自動計算・確認
...

Sheet Items
A1: ITEMS / 商品明細：青い入力欄を上から使用・最大30商品
A2: sku | B2: description | C2: hs_code | D2: origin_country | E2: quantity | F2: unit | G2: unit_price | H2: net_weight | I2: gross_weight | J2: weight_unit | K2: line_total | L2: memo | M2: check | N2: position
K3: =IF(OR(B3="",E3="",G3=""),"",ROUND(E3*G3,Header!$B$7)) | M3: =IF(COUNTA(A3:J3)=0,"",IF(OR(B3="",D3="",NOT(ISNUMBER(E3)),E3<=0,F3="",NOT(ISNUMBER(G3)),G3<0,G3<>ROUND(G3,4)),"CHECK REQUIRED FIELDS",IF(LEN(B3)>110,"CHECK DESCRIPTION LENGTH","OK"))) | N3: =IF(B3="","",1)
K4: =IF(OR(B4="",E4="",G4=""),"",ROUND(E4*G4,Header!$B$7)) | M4: =IF(COUNTA(A4:J4)=0,"",IF(OR(B4="",D4="",NOT(ISNUMBER(E4)),E4<=0,F4="",NOT(ISNUMBER(G4)),G4<0,G4<>ROUND(G4,4)),"CHECK REQUIRED FIELDS",IF(LEN(B4)>110,"CHECK DESCRIPTION LENGTH","OK"))) | N4: =IF(B4="","",2)
K5: =IF(OR(B5="",E5="",G5=""),"",ROUND(E5*G5,Header!$B$7)) | M5: =IF(COUNTA(A5:J5)=0,"",IF(OR(B5="",D5="",NOT(ISNUMBER(E5)),E5<=0,F5="",NOT(ISNUMBER(G5)),G5<0,G5<>ROUND(G5,4)),"CHECK REQUIRED FIELDS",IF(LEN(B5)>110,"CHECK DESCRIPTION LENGTH","OK"))) | N5: =IF(B5="","",3)
K6: =IF(OR(B6="",E6="",G6=""),"",ROUND(E6*G6,Header!$B$7)) | M6: =IF(COUNTA(A6:J6)=0,"",IF(OR(B6="",D6="",NOT(ISNUMBER(E6)),E6<=0,F6="",NOT(ISNUMBER(G6)),G6<0,G6<>ROUND(G6,4)),"CHECK REQUIRED FIELDS",IF(LEN(B6)>110,"CHECK DESCRIPTION LENGTH","OK"))) | N6: =IF(B6="","",4)
K7: =IF(OR(B7="",E7="",G7=""),"",ROUND(E7*G7,Header!$B$7)) | M7: =IF(COUNTA(A7:J7)=0,"",IF(OR(B7="",D7="",NOT(ISNUMBER(E7)),E7<=0,F7="",NOT(ISNUMBER(G7)),G7<0,G7<>ROUND(G7,4)),"CHECK REQUIRED FIELDS",IF(LEN(B7)>110,"CHECK DESCRIPTION LENGTH","OK"))) | N7: =IF(B7="","",5)
K8: =IF(OR(B8="",E8="",G8=""),"",ROUND(E8*G8,Header!$B$7)) | M8: =IF(COUNTA(A8:J8)=0,"",IF(OR(B8="",D8="",NOT(ISNUMBER(E8)),E8<=0,F8="",NOT(ISNUMBER(G8)),G8<0,G8<>ROUND(G8,4)),"CHECK REQUIRED FIELDS",IF(LEN(B8)>110,"CHECK DESCRIPTION LENGTH","OK"))) | N8: =IF(B8="","",6)
K9: =IF(OR(B9="",E9="",G9=""),"",ROUND(E9*G9,Header!$B$7)) | M9: =IF(COUNTA(A9:J9)=0,"",IF(OR(B9="",D9="",NOT(ISNUMBER(E9)),E9<=0,F9="",NOT(ISNUMBER(G9)),G9<0,G9<>ROUND(G9,4)),"CHECK REQUIRED FIELDS",IF(LEN(B9)>110,"CHECK DESCRIPTION LENGTH","OK"))) | N9: =IF(B9="","",7)
K10: =IF(OR(B10="",E10="",G10=""),"",ROUND(E10*G10,Header!$B$7)) | M10: =IF(COUNTA(A10:J10)=0,"",IF(OR(B10="",D10="",NOT(ISNUMBER(E10)),E10<=0,F10="",NOT(ISNUMBER(G10)),G10<0,G10<>ROUND(G10,4)),"CHECK REQUIRED FIELDS",IF(LEN(B10)>110,"CHECK DESCRIPTION LENGTH","OK"))) | N10: =IF(B10="","",8)
K11: =IF(OR(B11="",E11="",G11=""),"",ROUND(E11*G11,Header!$B$7)) | M11: =IF(COUNTA(A11:J11)=0,"",IF(OR(B11="",D11="",NOT(ISNUMBER(E11)),E11<=0,F11="",NOT(ISNUMBER(G11)),G11<0,G11<>ROUND(G11,4)),"CHECK REQUIRED FIELDS",IF(LEN(B11)>110,"CHECK DESCRIPTION LENGTH","OK"))) | N11: =IF(B11="","",9)
K12: =IF(OR(B12="",E12="",G12=""),"",ROUND(E12*G12,Header!$B$7)) | M12: =IF(COUNTA(A12:J12)=0,"",IF(OR(B12="",D12="",NOT(ISNUMBER(E12)),E12<=0,F12="",NOT(ISNUMBER(G12)),G12<0,G12<>ROUND(G12,4)),"CHECK REQUIRED FIELDS",IF(LEN(B12)>110,"CHECK DESCRIPTION LENGTH","OK"))) | N12: =IF(B12="","",10)
K13: =IF(OR(B13="",E13="",G13=""),"",ROUND(E13*G13,Header!$B$7)) | M13: =IF(COUNTA(A13:J13)=0,"",IF(OR(B13="",D13="",NOT(ISNUMBER(E13)),E13<=0,F13="",NOT(ISNUMBER(G13)),G13<0,G13<>ROUND(G13,4)),"CHECK REQUIRED FIELDS",IF(LEN(B13)>110,"CHECK DESCRIPTION LENGTH","OK"))) | N13: =IF(B13="","",11)
K14: =IF(OR(B14="",E14="",G14=""),"",ROUND(E14*G14,Header!$B$7)) | M14: =IF(COUNTA(A14:J14)=0,"",IF(OR(B14="",D14="",NOT(ISNUMBER(E14)),E14<=0,F14="",NOT(ISNUMBER(G14)),G14<0,G14<>ROUND(G14,4)),"CHECK REQUIRED FIELDS",IF(LEN(B14)>110,"CHECK DESCRIPTION LENGTH","OK"))) | N14: =IF(B14="","",12)
K15: =IF(OR(B15="",E15="",G15=""),"",ROUND(E15*G15,Header!$B$7)) | M15: =IF(COUNTA(A15:J15)=0,"",IF(OR(B15="",D15="",NOT(ISNUMBER(E15)),E15<=0,F15="",NOT(ISNUMBER(G15)),G15<0,G15<>ROUND(G15,4)),"CHECK REQUIRED FIELDS",IF(LEN(B15)>110,"CHECK DESCRIPTION LENGTH","OK"))) | N15: =IF(B15="","",13)
K16: =IF(OR(B16="",E16="",G16=""),"",ROUND(E16*G16,Header!$B$7)) | M16: =IF(COUNTA(A16:J16)=0,"",IF(OR(B16="",D16="",NOT(ISNUMBER(E16)),E16<=0,F16="",NOT(ISNUMBER(G16)),G16<0,G16<>ROUND(G16,4)),"CHECK REQUIRED FIELDS",IF(LEN(B16)>110,"CHECK DESCRIPTION LENGTH","OK"))) | N16: =IF(B16="","",14)
K17: =IF(OR(B17="",E17="",G17=""),"",ROUND(E17*G17,Header!$B$7)) | M17: =IF(COUNTA(A17:J17)=0,"",IF(OR(B17="",D17="",NOT(ISNUMBER(E17)),E17<=0,F17="",NOT(ISNUMBER(G17)),G17<0,G17<>ROUND(G17,4)),"CHECK REQUIRED FIELDS",IF(LEN(B17)>110,"CHECK DESCRIPTION LENGTH","OK"))) | N17: =IF(B17="","",15)
K18: =IF(OR(B18="",E18="",G18=""),"",ROUND(E18*G18,Header!$B$7)) | M18: =IF(COUNTA(A18:J18)=0,"",IF(OR(B18="",D18="",NOT(ISNUMBER(E18)),E18<=0,F18="",NOT(ISNUMBER(G18)),G18<0,G18<>ROUND(G18,4)),"CHECK REQUIRED FIELDS",IF(LEN(B18)>110,"CHECK DESCRIPTION LENGTH","OK"))) | N18: =IF(B18="","",16)
K19: =IF(OR(B19="",E19="",G19=""),"",ROUND(E19*G19,Header!$B$7)) | M19: =IF(COUNTA(A19:J19)=0,"",IF(OR(B19="",D19="",NOT(ISNUMBER(E19)),E19<=0,F19="",NOT(ISNUMBER(G19)),G19<0,G19<>ROUND(G19,4)),"CHECK REQUIRED FIELDS",IF(LEN(B19)>110,"CHECK DESCRIPTION LENGTH","OK"))) | N19: =IF(B19="","",17)
K20: =IF(OR(B20="",E20="",G20=""),"",ROUND(E20*G20,Header!$B$7)) | M20: =IF(COUNTA(A20:J20)=0,"",IF(OR(B20="",D20="",NOT(ISNUMBER(E20)),E20<=0,F20="",NOT(ISNUMBER(G20)),G20<0,G20<>ROUND(G20,4)),"CHECK REQUIRED FIELDS",IF(LEN(B20)>110,"CHECK DESCRIPTION LENGTH","OK"))) | N20: =IF(B20="","",18)
K21: =IF(OR(B21="",E21="",G21=""),"",ROUND(E21*G21,Header!$B$7)) | M21: =IF(COUNTA(A21:J21)=0,"",IF(OR(B21="",D21="",NOT(ISNUMBER(E21)),E21<=0,F21="",NOT(ISNUMBER(G21)),G21<0,G21<>ROUND(G21,4)),"CHECK REQUIRED FIELDS",IF(LEN(B21)>110,"CHECK DESCRIPTION LENGTH","OK"))) | N21: =IF(B21="","",19)
K22: =IF(OR(B22="",E22="",G22=""),"",ROUND(E22*G22,Header!$B$7)) | M22: =IF(COUNTA(A22:J22)=0,"",IF(OR(B22="",D22="",NOT(ISNUMBER(E22)),E22<=0,F22="",NOT(ISNUMBER(G22)),G22<0,G22<>ROUND(G22,4)),"CHECK REQUIRED FIELDS",IF(LEN(B22)>110,"CHECK DESCRIPTION LENGTH","OK"))) | N22: =IF(B22="","",20)
K23: =IF(OR(B23="",E23="",G23=""),"",ROUND(E23*G23,Header!$B$7)) | M23: =IF(COUNTA(A23:J23)=0,"",IF(OR(B23="",D23="",NOT(ISNUMBER(E23)),E23<=0,F23="",NOT(ISNUMBER(G23)),G23<0,G23<>ROUND(G23,4)),"CHECK REQUIRED FIELDS",IF(LEN(B23)>110,"CHECK DESCRIPTION LENGTH","OK"))) | N23: =IF(B23="","",21)
K24: =IF(OR(B24="",E24="",G24=""),"",ROUND(E24*G24,Header!$B$7)) | M24: =IF(COUNTA(A24:J24)=0,"",IF(OR(B24="",D24="",NOT(ISNUMBER(E24)),E24<=0,F24="",NOT(ISNUMBER(G24)),G24<0,G24<>ROUND(G24,4)),"CHECK REQUIRED FIELDS",IF(LEN(B24)>110,"CHECK DESCRIPTION LENGTH","OK"))) | N24: =IF(B24="","",22)
K25: =IF(OR(B25="",E25="",G25=""),"",ROUND(E25*G25,Header!$B$7)) | M25: =IF(COUNTA(A25:J25)=0,"",IF(OR(B25="",D25="",NOT(ISNUMBER(E25)),E25<=0,F25="",NOT(ISNUMBER(G25)),G25<0,G25<>ROUND(G25,4)),"CHECK REQUIRED FIELDS",IF(LEN(B25)>110,"CHECK DESCRIPTION LENGTH","OK"))) | N25: =IF(B25="","",23)
K26: =IF(OR(B26="",E26="",G26=""),"",ROUND(E26*G26,Header!$B$7)) | M26: =IF(COUNTA(A26:J26)=0,"",IF(OR(B26="",D26="",NOT(ISNUMBER(E26)),E26<=0,F26="",NOT(ISNUMBER(G26)),G26<0,G26<>ROUND(G26,4)),"CHECK REQUIRED FIELDS",IF(LEN(B26)>110,"CHECK DESCRIPTION LENGTH","OK"))) | N26: =IF(B26="","",24)
K27: =IF(OR(B27="",E27="",G27=""),"",ROUND(E27*G27,Header!$B$7)) | M27: =IF(COUNTA(A27:J27)=0,"",IF(OR(B27="",D27="",NOT(ISNUMBER(E27)),E27<=0,F27="",NOT(ISNUMBER(G27)),G27<0,G27<>ROUND(G27,4)),"CHECK REQUIRED FIELDS",IF(LEN(B27)>110,"CHECK DESCRIPTION LENGTH","OK"))) | N27: =IF(B27="","",25)
K28: =IF(OR(B28="",E28="",G28=""),"",ROUND(E28*G28,Header!$B$7)) | M28: =IF(COUNTA(A28:J28)=0,"",IF(OR(B28="",D28="",NOT(ISNUMBER(E28)),E28<=0,F28="",NOT(ISNUMBER(G28)),G28<0,G28<>ROUND(G28,4)),"CHECK REQUIRED FIELDS",IF(LEN(B28)>110,"CHECK DESCRIPTION LENGTH","OK"))) | N28: =IF(B28="","",26)
K29: =IF(OR(B29="",E29="",G29=""),"",ROUND(E29*G29,Header!$B$7)) | M29: =IF(COUNTA(A29:J29)=0,"",IF(OR(B29="",D29="",NOT(ISNUMBER(E29)),E29<=0,F29="",NOT(ISNUMBER(G29)),G29<0,G29<>ROUND(G29,4)),"CHECK REQUIRED FIELDS",IF(LEN(B29)>110,"CHECK DESCRIPTION LENGTH","OK"))) | N29: =IF(B29="","",27)
K30: =IF(OR(B30="",E30="",G30=""),"",ROUND(E30*G30,Header!$B$7)) | M30: =IF(COUNTA(A30:J30)=0,"",IF(OR(B30="",D30="",NOT(ISNUMBER(E30)),E30<=0,F30="",NOT(ISNUMBER(G30)),G30<0,G30<>ROUND(G30,4)),"CHECK REQUIRED FIELDS",IF(LEN(B30)>110,"CHECK DESCRIPTION LENGTH","OK"))) | N30: =IF(B30="","",28)
K31: =IF(OR(B31="",E31="",G31=""),"",ROUND(E31*G31,Header!$B$7)) | M31: =IF(COUNTA(A31:J31)=0,"",IF(OR(B31="",D31="",NOT(ISNUMBER(E31)),E31<=0,F31="",NOT(ISNUMBER(G31)),G31<0,G31<>ROUND(G31,4)),"CHECK REQUIRED FIELDS",IF(LEN(B31)>110,"CHECK DESCRIPTION LENGTH","OK"))) | N31: =IF(B31="","",29)
K32: =IF(OR(B32="",E32="",G32=""),"",ROUND(E32*G32,Header!$B$7)) | M32: =IF(COUNTA(A32:J32)=0,"",IF(OR(B32="",D32="",NOT(ISNUMBER(E32)),E32<=0,F32="",NOT(ISNUMBER(G32)),G32<0,G32<>ROUND(G32,4)),"CHECK REQUIRED FIELDS",IF(LEN(B32)>110,"CHECK DESCRIPTION LENGTH","OK"))) | N32: =IF(B32="","",30)

Sheet Invoice_1
A1: =IF(1<=Header!B49,IF(Header!B3="PROFORMA","PROFORMA INVOICE","COMMERCIAL INVOICE"),"UNUSED PAGE — DO NOT PRINT") -> PROFORMA INVOICE
A2: =IF(Header!B45="DRAFT","DRAFT / NOT FOR SHIPMENT",IF(Header!B53<>"BASIC CHECK OK","CHECK INPUTS BEFORE ISSUE","")) -> DRAFT / NOT FOR SHIPMENT
A3: ="Invoice No. "&IF(Header!B4="","",Header!B4)&" | Date "&IF(Header!B5="","",Header!B5) -> Invoice No. | Date | E3: ="Currency "&IF(Header!B6="","",Header!B6)&" | Page 1 / "&Header!B49 -> Currency USD | Page 1 / 1
A4: EXPORTER / SELLER | E4: BUYER / BILL TO
A5: =IF(Header!B18="","",IF(Header!B18="","",Header!B18)&CHAR(10)&IF(Header!B19="","",Header!B19)&CHAR(10)&IF(Header!B20="","",Header!B20)&IF(Header!B21="","",CHAR(10)&"Tax / Reg. ID: "&Header!B21)) | E5: =IF(Header!B22="","",IF(Header!B22="","",Header!B22)&CHAR(10)&IF(Header!B23="","",Header!B23)&CHAR(10)&IF(Header!B24="","",Header!B24)&IF(Header!B25="","",CHAR(10)&"Tax / Reg. ID: "&Header!B25))
A8: SHIP TO / CONSIGNEE | E8: IMPORTER
A9: =IF(Header!B26="","Same as buyer",IF(Header!B26="","",Header!B26)&CHAR(10)&IF(Header!B27="","",Header!B27)&CHAR(10)&IF(Header!B28="","",Header!B28)) -> Same as buyer | E9: =IF(Header!B29="","Same as buyer",IF(Header!B29="","",Header!B29)&CHAR(10)&IF(Header!B30="","",Header!B30)&IF(Header!B31="","",CHAR(10)&"Tax / Reg. ID: "&Header!B31)) -> Same as buyer
A11: ="Terms: "&IF(Header!B9="","",Header!B9)&" | Payment: "&IF(Header!B8="","",Header!B8) -> Terms: | Payment:
A12: ="Purpose: "&IF(Header!B10="","",Header!B10)&" | PO: "&IF(Header!B11="","",Header!B11)&IF(Header!B3="PROFORMA"," | Valid until: "&IF(Header!B12="","",Header!B12),"") -> Purpose: | PO: | Valid until:
A13: ="From: "&IF(Header!B16="","",Header!B16)&" → "&IF(Header!B17="","",Header!B17)&" | Ship date: "&IF(Header!B13="","",Header!B13)&" | "&IF(Header!B14="","",Header!B14) -> From: Japan → | Ship date: |
A14: ="Carrier / AWB: "&IF(Header!B15="","",Header!B15) -> Carrier / AWB:
A15: No. | B15: Description / SKU | C15: HS code | D15: Origin | E15: Qty | F15: Unit | G15: Unit price | H15: Amount
A16: =IF(Items!B3="","",1) | B16: =IF(Items!B3="","",Items!B3&IF(Items!A3="","",CHAR(10)&"SKU: "&Items!A3)) | C16: =IF(Items!B3="","",IF(Items!C3="","",Items!C3)) | D16: =IF(Items!B3="","",IF(Items!D3="","",Items!D3)) | E16: =IF(Items!B3="","",IF(Items!E3="","",Items!E3)) | F16: =IF(Items!B3="","",IF(Items!F3="","",Items!F3)) | G16: =IF(Items!B3="","",IF(Items!G3="","",Items!G3)) | H16: =IF(Items!B3="","",IF(Items!K3="","",Items!K3))
A17: =IF(Items!B4="","",2) | B17: =IF(Items!B4="","",Items!B4&IF(Items!A4="","",CHAR(10)&"SKU: "&Items!A4)) | C17: =IF(Items!B4="","",IF(Items!C4="","",Items!C4)) | D17: =IF(Items!B4="","",IF(Items!D4="","",Items!D4)) | E17: =IF(Items!B4="","",IF(Items!E4="","",Items!E4)) | F17: =IF(Items!B4="","",IF(Items!F4="","",Items!F4)) | G17: =IF(Items!B4="","",IF(Items!G4="","",Items!G4)) | H17: =IF(Items!B4="","",IF(Items!K4="","",Items!K4))
A18: =IF(Items!B5="","",3) | B18: =IF(Items!B5="","",Items!B5&IF(Items!A5="","",CHAR(10)&"SKU: "&Items!A5)) | C18: =IF(Items!B5="","",IF(Items!C5="","",Items!C5)) | D18: =IF(Items!B5="","",IF(Items!D5="","",Items!D5)) | E18: =IF(Items!B5="","",IF(Items!E5="","",Items!E5)) | F18: =IF(Items!B5="","",IF(Items!F5="","",Items!F5)) | G18: =IF(Items!B5="","",IF(Items!G5="","",Items!G5)) | H18: =IF(Items!B5="","",IF(Items!K5="","",Items!K5))
A19: =IF(Items!B6="","",4) | B19: =IF(Items!B6="","",Items!B6&IF(Items!A6="","",CHAR(10)&"SKU: "&Items!A6)) | C19: =IF(Items!B6="","",IF(Items!C6="","",Items!C6)) | D19: =IF(Items!B6="","",IF(Items!D6="","",Items!D6)) | E19: =IF(Items!B6="","",IF(Items!E6="","",Items!E6)) | F19: =IF(Items!B6="","",IF(Items!F6="","",Items!F6)) | G19: =IF(Items!B6="","",IF(Items!G6="","",Items!G6)) | H19: =IF(Items!B6="","",IF(Items!K6="","",Items!K6))
A20: =IF(Items!B7="","",5) | B20: =IF(Items!B7="","",Items!B7&IF(Items!A7="","",CHAR(10)&"SKU: "&Items!A7)) | C20: =IF(Items!B7="","",IF(Items!C7="","",Items!C7)) | D20: =IF(Items!B7="","",IF(Items!D7="","",Items!D7)) | E20: =IF(Items!B7="","",IF(Items!E7="","",Items!E7)) | F20: =IF(Items!B7="","",IF(Items!F7="","",Items!F7)) | G20: =IF(Items!B7="","",IF(Items!G7="","",Items!G7)) | H20: =IF(Items!B7="","",IF(Items!K7="","",Items!K7))
A21: =IF(Items!B8="","",6) | B21: =IF(Items!B8="","",Items!B8&IF(Items!A8="","",CHAR(10)&"SKU: "&Items!A8)) | C21: =IF(Items!B8="","",IF(Items!C8="","",Items!C8)) | D21: =IF(Items!B8="","",IF(Items!D8="","",Items!D8)) | E21: =IF(Items!B8="","",IF(Items!E8="","",Items!E8)) | F21: =IF(Items!B8="","",IF(Items!F8="","",Items!F8)) | G21: =IF(Items!B8="","",IF(Items!G8="","",Items!G8)) | H21: =IF(Items!B8="","",IF(Items!K8="","",Items!K8))
A22: =IF(Items!B9="","",7) | B22: =IF(Items!B9="","",Items!B9&IF(Items!A9="","",CHAR(10)&"SKU: "&Items!A9)) | C22: =IF(Items!B9="","",IF(Items!C9="","",Items!C9)) | D22: =IF(Items!B9="","",IF(Items!D9="","",Items!D9)) | E22: =IF(Items!B9="","",IF(Items!E9="","",Items!E9)) | F22: =IF(Items!B9="","",IF(Items!F9="","",Items!F9)) | G22: =IF(Items!B9="","",IF(Items!G9="","",Items!G9)) | H22: =IF(Items!B9="","",IF(Items!K9="","",Items!K9))
A23: =IF(Items!B10="","",8) | B23: =IF(Items!B10="","",Items!B10&IF(Items!A10="","",CHAR(10)&"SKU: "&Items!A10)) | C23: =IF(Items!B10="","",IF(Items!C10="","",Items!C10)) | D23: =IF(Items!B10="","",IF(Items!D10="","",Items!D10)) | E23: =IF(Items!B10="","",IF(Items!E10="","",Items!E10)) | F23: =IF(Items!B10="","",IF(Items!F10="","",Items!F10)) | G23: =IF(Items!B10="","",IF(Items!G10="","",Items!G10)) | H23: =IF(Items!B10="","",IF(Items!K10="","",Items!K10))
A24: =IF(Items!B11="","",9) | B24: =IF(Items!B11="","",Items!B11&IF(Items!A11="","",CHAR(10)&"SKU: "&Items!A11)) | C24: =IF(Items!B11="","",IF(Items!C11="","",Items!C11)) | D24: =IF(Items!B11="","",IF(Items!D11="","",Items!D11)) | E24: =IF(Items!B11="","",IF(Items!E11="","",Items!E11)) | F24: =IF(Items!B11="","",IF(Items!F11="","",Items!F11)) | G24: =IF(Items!B11="","",IF(Items!G11="","",Items!G11)) | H24: =IF(Items!B11="","",IF(Items!K11="","",Items!K11))
A25: =IF(Items!B12="","",10) | B25: =IF(Items!B12="","",Items!B12&IF(Items!A12="","",CHAR(10)&"SKU: "&Items!A12)) | C25: =IF(Items!B12="","",IF(Items!C12="","",Items!C12)) | D25: =IF(Items!B12="","",IF(Items!D12="","",Items!D12)) | E25: =IF(Items!B12="","",IF(Items!E12="","",Items!E12)) | F25: =IF(Items!B12="","",IF(Items!F12="","",Items!F12)) | G25: =IF(Items!B12="","",IF(Items!G12="","",Items!G12)) | H25: =IF(Items!B12="","",IF(Items!K12="","",Items!K12))
A26: =IF(1=Header!B49,"Packages: "&IF(Header!B32="","",Header!B32)&" "&IF(Header!B33="","",Header!B33)&CHAR(10)&"Net / Gross weight: "&IF(Header!B34="","",Header!B34)&" / "&IF(Header!B35="","",Header!B35)&" "&IF(Header!B36="","",Header!B36),IF(1<=Header!B49,"Continued on next page", "")) -> Packages: Net / Gross weight: / kg | F26: =IF(1=Header!B49,"Subtotal","") -> Subtotal | H26: =IF(1=Header!B49,Header!B50,"") -> 0
F27: =IF(1=Header!B49,"Freight","") -> Freight | H27: =IF(1=Header!B49,Header!B37,"") -> 0
A28: =IF(1=Header!B49,IF(Header!B40="","",Header!B40),"") | F28: =IF(1=Header!B49,"Insurance","") -> Insurance | H28: =IF(1=Header!B49,Header!B38,"") -> 0
F29: =IF(1=Header!B49,"Other charges","") -> Other charges | H29: =IF(1=Header!B49,Header!B39,"") -> 0
F30: =IF(1=Header!B49,"TOTAL","") -> TOTAL | H30: =IF(1=Header!B49,Header!B51,"") -> 0
A31: =IF(1=Header!B49,IF(Header!B3="COMMERCIAL",IF(Header!B43="","",Header!B43),IF(Header!B44="","",Header!B44)),"") -> Proforma invoice for quotation purposes.
A33: =IF(1=Header!B49,"Authorized signatory","") -> Authorized signatory | E33: =IF(1=Header!B49,"Signature / Date","") -> Signature / Date
A34: =IF(AND(1=Header!B49,Header!B41<>""),IF(Header!B41="","",Header!B41)&CHAR(10)&IF(Header!B42="","",Header!B42),"")
A37: =IF(1<=Header!B49,IF(Header!B4="","",Header!B4)&" • 1 / "&Header!B49,"") -> • 1 / 1

Sheet Invoice_2
A1: =IF(2<=Header!B49,IF(Header!B3="PROFORMA","PROFORMA INVOICE","COMMERCIAL INVOICE"),"UNUSED PAGE — DO NOT PRINT") -> UNUSED PAGE — DO NOT PRINT
A2: =IF(Header!B45="DRAFT","DRAFT / NOT FOR SHIPMENT",IF(Header!B53<>"BASIC CHECK OK","CHECK INPUTS BEFORE ISSUE","")) -> DRAFT / NOT FOR SHIPMENT
A3: ="Invoice No. "&IF(Header!B4="","",Header!B4)&" | Date "&IF(Header!B5="","",Header!B5) -> Invoice No. | Date | E3: ="Currency "&IF(Header!B6="","",Header!B6)&" | Page 2 / "&Header!B49 -> Currency USD | Page 2 / 1
A4: EXPORTER / SELLER | E4: BUYER / BILL TO
A5: =IF(Header!B18="","",IF(Header!B18="","",Header!B18)&CHAR(10)&IF(Header!B19="","",Header!B19)&CHAR(10)&IF(Header!B20="","",Header!B20)&IF(Header!B21="","",CHAR(10)&"Tax / Reg. ID: "&Header!B21)) | E5: =IF(Header!B22="","",IF(Header!B22="","",Header!B22)&CHAR(10)&IF(Header!B23="","",Header!B23)&CHAR(10)&IF(Header!B24="","",Header!B24)&IF(Header!B25="","",CHAR(10)&"Tax / Reg. ID: "&Header!B25))
A8: SHIP TO / CONSIGNEE | E8: IMPORTER
A9: =IF(Header!B26="","Same as buyer",IF(Header!B26="","",Header!B26)&CHAR(10)&IF(Header!B27="","",Header!B27)&CHAR(10)&IF(Header!B28="","",Header!B28)) -> Same as buyer | E9: =IF(Header!B29="","Same as buyer",IF(Header!B29="","",Header!B29)&CHAR(10)&IF(Header!B30="","",Header!B30)&IF(Header!B31="","",CHAR(10)&"Tax / Reg. ID: "&Header!B31)) -> Same as buyer
A11: ="Terms: "&IF(Header!B9="","",Header!B9)&" | Payment: "&IF(Header!B8="","",Header!B8) -> Terms: | Payment:
A12: ="Purpose: "&IF(Header!B10="","",Header!B10)&" | PO: "&IF(Header!B11="","",Header!B11)&IF(Header!B3="PROFORMA"," | Valid until: "&IF(Header!B12="","",Header!B12),"") -> Purpose: | PO: | Valid until:
A13: ="From: "&IF(Header!B16="","",Header!B16)&" → "&IF(Header!B17="","",Header!B17)&" | Ship date: "&IF(Header!B13="","",Header!B13)&" | "&IF(Header!B14="","",Header!B14) -> From: Japan → | Ship date: |
A14: ="Carrier / AWB: "&IF(Header!B15="","",Header!B15) -> Carrier / AWB:
A15: No. | B15: Description / SKU | C15: HS code | D15: Origin | E15: Qty | F15: Unit | G15: Unit price | H15: Amount
A16: =IF(Items!B13="","",11) | B16: =IF(Items!B13="","",Items!B13&IF(Items!A13="","",CHAR(10)&"SKU: "&Items!A13)) | C16: =IF(Items!B13="","",IF(Items!C13="","",Items!C13)) | D16: =IF(Items!B13="","",IF(Items!D13="","",Items!D13)) | E16: =IF(Items!B13="","",IF(Items!E13="","",Items!E13)) | F16: =IF(Items!B13="","",IF(Items!F13="","",Items!F13)) | G16: =IF(Items!B13="","",IF(Items!G13="","",Items!G13)) | H16: =IF(Items!B13="","",IF(Items!K13="","",Items!K13))
A17: =IF(Items!B14="","",12) | B17: =IF(Items!B14="","",Items!B14&IF(Items!A14="","",CHAR(10)&"SKU: "&Items!A14)) | C17: =IF(Items!B14="","",IF(Items!C14="","",Items!C14)) | D17: =IF(Items!B14="","",IF(Items!D14="","",Items!D14)) | E17: =IF(Items!B14="","",IF(Items!E14="","",Items!E14)) | F17: =IF(Items!B14="","",IF(Items!F14="","",Items!F14)) | G17: =IF(Items!B14="","",IF(Items!G14="","",Items!G14)) | H17: =IF(Items!B14="","",IF(Items!K14="","",Items!K14))
A18: =IF(Items!B15="","",13) | B18: =IF(Items!B15="","",Items!B15&IF(Items!A15="","",CHAR(10)&"SKU: "&Items!A15)) | C18: =IF(Items!B15="","",IF(Items!C15="","",Items!C15)) | D18: =IF(Items!B15="","",IF(Items!D15="","",Items!D15)) | E18: =IF(Items!B15="","",IF(Items!E15="","",Items!E15)) | F18: =IF(Items!B15="","",IF(Items!F15="","",Items!F15)) | G18: =IF(Items!B15="","",IF(Items!G15="","",Items!G15)) | H18: =IF(Items!B15="","",IF(Items!K15="","",Items!K15))
A19: =IF(Items!B16="","",14) | B19: =IF(Items!B16="","",Items!B16&IF(Items!A16="","",CHAR(10)&"SKU: "&Items!A16)) | C19: =IF(Items!B16="","",IF(Items!C16="","",Items!C16)) | D19: =IF(Items!B16="","",IF(Items!D16="","",Items!D16)) | E19: =IF(Items!B16="","",IF(Items!E16="","",Items!E16)) | F19: =IF(Items!B16="","",IF(Items!F16="","",Items!F16)) | G19: =IF(Items!B16="","",IF(Items!G16="","",Items!G16)) | H19: =IF(Items!B16="","",IF(Items!K16="","",Items!K16))
A20: =IF(Items!B17="","",15) | B20: =IF(Items!B17="","",Items!B17&IF(Items!A17="","",CHAR(10)&"SKU: "&Items!A17)) | C20: =IF(Items!B17="","",IF(Items!C17="","",Items!C17)) | D20: =IF(Items!B17="","",IF(Items!D17="","",Items!D17)) | E20: =IF(Items!B17="","",IF(Items!E17="","",Items!E17)) | F20: =IF(Items!B17="","",IF(Items!F17="","",Items!F17)) | G20: =IF(Items!B17="","",IF(Items!G17="","",Items!G17)) | H20: =IF(Items!B17="","",IF(Items!K17="","",Items!K17))
A21: =IF(Items!B18="","",16) | B21: =IF(Items!B18="","",Items!B18&IF(Items!A18="","",CHAR(10)&"SKU: "&Items!A18)) | C21: =IF(Items!B18="","",IF(Items!C18="","",Items!C18)) | D21: =IF(Items!B18="","",IF(Items!D18="","",Items!D18)) | E21: =IF(Items!B18="","",IF(Items!E18="","",Items!E18)) | F21: =IF(Items!B18="","",IF(Items!F18="","",Items!F18)) | G21: =IF(Items!B18="","",IF(Items!G18="","",Items!G18)) | H21: =IF(Items!B18="","",IF(Items!K18="","",Items!K18))
A22: =IF(Items!B19="","",17) | B22: =IF(Items!B19="","",Items!B19&IF(Items!A19="","",CHAR(10)&"SKU: "&Items!A19)) | C22: =IF(Items!B19="","",IF(Items!C19="","",Items!C19)) | D22: =IF(Items!B19="","",IF(Items!D19="","",Items!D19)) | E22: =IF(Items!B19="","",IF(Items!E19="","",Items!E19)) | F22: =IF(Items!B19="","",IF(Items!F19="","",Items!F19)) | G22: =IF(Items!B19="","",IF(Items!G19="","",Items!G19)) | H22: =IF(Items!B19="","",IF(Items!K19="","",Items!K19))
A23: =IF(Items!B20="","",18) | B23: =IF(Items!B20="","",Items!B20&IF(Items!A20="","",CHAR(10)&"SKU: "&Items!A20)) | C23: =IF(Items!B20="","",IF(Items!C20="","",Items!C20)) | D23: =IF(Items!B20="","",IF(Items!D20="","",Items!D20)) | E23: =IF(Items!B20="","",IF(Items!E20="","",Items!E20)) | F23: =IF(Items!B20="","",IF(Items!F20="","",Items!F20)) | G23: =IF(Items!B20="","",IF(Items!G20="","",Items!G20)) | H23: =IF(Items!B20="","",IF(Items!K20="","",Items!K20))
A24: =IF(Items!B21="","",19) | B24: =IF(Items!B21="","",Items!B21&IF(Items!A21="","",CHAR(10)&"SKU: "&Items!A21)) | C24: =IF(Items!B21="","",IF(Items!C21="","",Items!C21)) | D24: =IF(Items!B21="","",IF(Items!D21="","",Items!D21)) | E24: =IF(Items!B21="","",IF(Items!E21="","",Items!E21)) | F24: =IF(Items!B21="","",IF(Items!F21="","",Items!F21)) | G24: =IF(Items!B21="","",IF(Items!G21="","",Items!G21)) | H24: =IF(Items!B21="","",IF(Items!K21="","",Items!K21))
A25: =IF(Items!B22="","",20) | B25: =IF(Items!B22="","",Items!B22&IF(Items!A22="","",CHAR(10)&"SKU: "&Items!A22)) | C25: =IF(Items!B22="","",IF(Items!C22="","",Items!C22)) | D25: =IF(Items!B22="","",IF(Items!D22="","",Items!D22)) | E25: =IF(Items!B22="","",IF(Items!E22="","",Items!E22)) | F25: =IF(Items!B22="","",IF(Items!F22="","",Items!F22)) | G25: =IF(Items!B22="","",IF(Items!G22="","",Items!G22)) | H25: =IF(Items!B22="","",IF(Items!K22="","",Items!K22))
A26: =IF(2=Header!B49,"Packages: "&IF(Header!B32="","",Header!B32)&" "&IF(Header!B33="","",Header!B33)&CHAR(10)&"Net / Gross weight: "&IF(Header!B34="","",Header!B34)&" / "&IF(Header!B35="","",Header!B35)&" "&IF(Header!B36="","",Header!B36),IF(2<=Header!B49,"Continued on next page", "")) | F26: =IF(2=Header!B49,"Subtotal","") | H26: =IF(2=Header!B49,Header!B50,"")
F27: =IF(2=Header!B49,"Freight","") | H27: =IF(2=Header!B49,Header!B37,"")
A28: =IF(2=Header!B49,IF(Header!B40="","",Header!B40),"") | F28: =IF(2=Header!B49,"Insurance","") | H28: =IF(2=Header!B49,Header!B38,"")
F29: =IF(2=Header!B49,"Other charges","") | H29: =IF(2=Header!B49,Header!B39,"")
F30: =IF(2=Header!B49,"TOTAL","") | H30: =IF(2=Header!B49,Header!B51,"")
A31: =IF(2=Header!B49,IF(Header!B3="COMMERCIAL",IF(Header!B43="","",Header!B43),IF(Header!B44="","",Header!B44)),"")
A33: =IF(2=Header!B49,"Authorized signatory","") | E33: =IF(2=Header!B49,"Signature / Date","")
A34: =IF(AND(2=Header!B49,Header!B41<>""),IF(Header!B41="","",Header!B41)&CHAR(10)&IF(Header!B42="","",Header!B42),"")
A37: =IF(2<=Header!B49,IF(Header!B4="","",Header!B4)&" • 2 / "&Header!B49,"")

Sheet Invoice_3
A1: =IF(3<=Header!B49,IF(Header!B3="PROFORMA","PROFORMA INVOICE","COMMERCIAL INVOICE"),"UNUSED PAGE — DO NOT PRINT") -> UNUSED PAGE — DO NOT PRINT
A2: =IF(Header!B45="DRAFT","DRAFT / NOT FOR SHIPMENT",IF(Header!B53<>"BASIC CHECK OK","CHECK INPUTS BEFORE ISSUE","")) -> DRAFT / NOT FOR SHIPMENT
A3: ="Invoice No. "&IF(Header!B4="","",Header!B4)&" | Date "&IF(Header!B5="","",Header!B5) -> Invoice No. | Date | E3: ="Currency "&IF(Header!B6="","",Header!B6)&" | Page 3 / "&Header!B49 -> Currency USD | Page 3 / 1
A4: EXPORTER / SELLER | E4: BUYER / BILL TO
A5: =IF(Header!B18="","",IF(Header!B18="","",Header!B18)&CHAR(10)&IF(Header!B19="","",Header!B19)&CHAR(10)&IF(Header!B20="","",Header!B20)&IF(Header!B21="","",CHAR(10)&"Tax / Reg. ID: "&Header!B21)) | E5: =IF(Header!B22="","",IF(Header!B22="","",Header!B22)&CHAR(10)&IF(Header!B23="","",Header!B23)&CHAR(10)&IF(Header!B24="","",Header!B24)&IF(Header!B25="","",CHAR(10)&"Tax / Reg. ID: "&Header!B25))
A8: SHIP TO / CONSIGNEE | E8: IMPORTER
A9: =IF(Header!B26="","Same as buyer",IF(Header!B26="","",Header!B26)&CHAR(10)&IF(Header!B27="","",Header!B27)&CHAR(10)&IF(Header!B28="","",Header!B28)) -> Same as buyer | E9: =IF(Header!B29="","Same as buyer",IF(Header!B29="","",Header!B29)&CHAR(10)&IF(Header!B30="","",Header!B30)&IF(Header!B31="","",CHAR(10)&"Tax / Reg. ID: "&Header!B31)) -> Same as buyer
A11: ="Terms: "&IF(Header!B9="","",Header!B9)&" | Payment: "&IF(Header!B8="","",Header!B8) -> Terms: | Payment:
A12: ="Purpose: "&IF(Header!B10="","",Header!B10)&" | PO: "&IF(Header!B11="","",Header!B11)&IF(Header!B3="PROFORMA"," | Valid until: "&IF(Header!B12="","",Header!B12),"") -> Purpose: | PO: | Valid until:
A13: ="From: "&IF(Header!B16="","",Header!B16)&" → "&IF(Header!B17="","",Header!B17)&" | Ship date: "&IF(Header!B13="","",Header!B13)&" | "&IF(Header!B14="","",Header!B14) -> From: Japan → | Ship date: |
A14: ="Carrier / AWB: "&IF(Header!B15="","",Header!B15) -> Carrier / AWB:
A15: No. | B15: Description / SKU | C15: HS code | D15: Origin | E15: Qty | F15: Unit | G15: Unit price | H15: Amount
A16: =IF(Items!B23="","",21) | B16: =IF(Items!B23="","",Items!B23&IF(Items!A23="","",CHAR(10)&"SKU: "&Items!A23)) | C16: =IF(Items!B23="","",IF(Items!C23="","",Items!C23)) | D16: =IF(Items!B23="","",IF(Items!D23="","",Items!D23)) | E16: =IF(Items!B23="","",IF(Items!E23="","",Items!E23)) | F16: =IF(Items!B23="","",IF(Items!F23="","",Items!F23)) | G16: =IF(Items!B23="","",IF(Items!G23="","",Items!G23)) | H16: =IF(Items!B23="","",IF(Items!K23="","",Items!K23))
A17: =IF(Items!B24="","",22) | B17: =IF(Items!B24="","",Items!B24&IF(Items!A24="","",CHAR(10)&"SKU: "&Items!A24)) | C17: =IF(Items!B24="","",IF(Items!C24="","",Items!C24)) | D17: =IF(Items!B24="","",IF(Items!D24="","",Items!D24)) | E17: =IF(Items!B24="","",IF(Items!E24="","",Items!E24)) | F17: =IF(Items!B24="","",IF(Items!F24="","",Items!F24)) | G17: =IF(Items!B24="","",IF(Items!G24="","",Items!G24)) | H17: =IF(Items!B24="","",IF(Items!K24="","",Items!K24))
A18: =IF(Items!B25="","",23) | B18: =IF(Items!B25="","",Items!B25&IF(Items!A25="","",CHAR(10)&"SKU: "&Items!A25)) | C18: =IF(Items!B25="","",IF(Items!C25="","",Items!C25)) | D18: =IF(Items!B25="","",IF(Items!D25="","",Items!D25)) | E18: =IF(Items!B25="","",IF(Items!E25="","",Items!E25)) | F18: =IF(Items!B25="","",IF(Items!F25="","",Items!F25)) | G18: =IF(Items!B25="","",IF(Items!G25="","",Items!G25)) | H18: =IF(Items!B25="","",IF(Items!K25="","",Items!K25))
A19: =IF(Items!B26="","",24) | B19: =IF(Items!B26="","",Items!B26&IF(Items!A26="","",CHAR(10)&"SKU: "&Items!A26)) | C19: =IF(Items!B26="","",IF(Items!C26="","",Items!C26)) | D19: =IF(Items!B26="","",IF(Items!D26="","",Items!D26)) | E19: =IF(Items!B26="","",IF(Items!E26="","",Items!E26)) | F19: =IF(Items!B26="","",IF(Items!F26="","",Items!F26)) | G19: =IF(Items!B26="","",IF(Items!G26="","",Items!G26)) | H19: =IF(Items!B26="","",IF(Items!K26="","",Items!K26))
A20: =IF(Items!B27="","",25) | B20: =IF(Items!B27="","",Items!B27&IF(Items!A27="","",CHAR(10)&"SKU: "&Items!A27)) | C20: =IF(Items!B27="","",IF(Items!C27="","",Items!C27)) | D20: =IF(Items!B27="","",IF(Items!D27="","",Items!D27)) | E20: =IF(Items!B27="","",IF(Items!E27="","",Items!E27)) | F20: =IF(Items!B27="","",IF(Items!F27="","",Items!F27)) | G20: =IF(Items!B27="","",IF(Items!G27="","",Items!G27)) | H20: =IF(Items!B27="","",IF(Items!K27="","",Items!K27))
A21: =IF(Items!B28="","",26) | B21: =IF(Items!B28="","",Items!B28&IF(Items!A28="","",CHAR(10)&"SKU: "&Items!A28)) | C21: =IF(Items!B28="","",IF(Items!C28="","",Items!C28)) | D21: =IF(Items!B28="","",IF(Items!D28="","",Items!D28)) | E21: =IF(Items!B28="","",IF(Items!E28="","",Items!E28)) | F21: =IF(Items!B28="","",IF(Items!F28="","",Items!F28)) | G21: =IF(Items!B28="","",IF(Items!G28="","",Items!G28)) | H21: =IF(Items!B28="","",IF(Items!K28="","",Items!K28))
A22: =IF(Items!B29="","",27) | B22: =IF(Items!B29="","",Items!B29&IF(Items!A29="","",CHAR(10)&"SKU: "&Items!A29)) | C22: =IF(Items!B29="","",IF(Items!C29="","",Items!C29)) | D22: =IF(Items!B29="","",IF(Items!D29="","",Items!D29)) | E22: =IF(Items!B29="","",IF(Items!E29="","",Items!E29)) | F22: =IF(Items!B29="","",IF(Items!F29="","",Items!F29)) | G22: =IF(Items!B29="","",IF(Items!G29="","",Items!G29)) | H22: =IF(Items!B29="","",IF(Items!K29="","",Items!K29))
A23: =IF(Items!B30="","",28) | B23: =IF(Items!B30="","",Items!B30&IF(Items!A30="","",CHAR(10)&"SKU: "&Items!A30)) | C23: =IF(Items!B30="","",IF(Items!C30="","",Items!C30)) | D23: =IF(Items!B30="","",IF(Items!D30="","",Items!D30)) | E23: =IF(Items!B30="","",IF(Items!E30="","",Items!E30)) | F23: =IF(Items!B30="","",IF(Items!F30="","",Items!F30)) | G23: =IF(Items!B30="","",IF(Items!G30="","",Items!G30)) | H23: =IF(Items!B30="","",IF(Items!K30="","",Items!K30))
A24: =IF(Items!B31="","",29) | B24: =IF(Items!B31="","",Items!B31&IF(Items!A31="","",CHAR(10)&"SKU: "&Items!A31)) | C24: =IF(Items!B31="","",IF(Items!C31="","",Items!C31)) | D24: =IF(Items!B31="","",IF(Items!D31="","",Items!D31)) | E24: =IF(Items!B31="","",IF(Items!E31="","",Items!E31)) | F24: =IF(Items!B31="","",IF(Items!F31="","",Items!F31)) | G24: =IF(Items!B31="","",IF(Items!G31="","",Items!G31)) | H24: =IF(Items!B31="","",IF(Items!K31="","",Items!K31))
A25: =IF(Items!B32="","",30) | B25: =IF(Items!B32="","",Items!B32&IF(Items!A32="","",CHAR(10)&"SKU: "&Items!A32)) | C25: =IF(Items!B32="","",IF(Items!C32="","",Items!C32)) | D25: =IF(Items!B32="","",IF(Items!D32="","",Items!D32)) | E25: =IF(Items!B32="","",IF(Items!E32="","",Items!E32)) | F25: =IF(Items!B32="","",IF(Items!F32="","",Items!F32)) | G25: =IF(Items!B32="","",IF(Items!G32="","",Items!G32)) | H25: =IF(Items!B32="","",IF(Items!K32="","",Items!K32))
A26: =IF(3=Header!B49,"Packages: "&IF(Header!B32="","",Header!B32)&" "&IF(Header!B33="","",Header!B33)&CHAR(10)&"Net / Gross weight: "&IF(Header!B34="","",Header!B34)&" / "&IF(Header!B35="","",Header!B35)&" "&IF(Header!B36="","",Header!B36),IF(3<=Header!B49,"Continued on next page", "")) | F26: =IF(3=Header!B49,"Subtotal","") | H26: =IF(3=Header!B49,Header!B50,"")
F27: =IF(3=Header!B49,"Freight","") | H27: =IF(3=Header!B49,Header!B37,"")
A28: =IF(3=Header!B49,IF(Header!B40="","",Header!B40),"") | F28: =IF(3=Header!B49,"Insurance","") | H28: =IF(3=Header!B49,Header!B38,"")
F29: =IF(3=Header!B49,"Other charges","") | H29: =IF(3=Header!B49,Header!B39,"")
F30: =IF(3=Header!B49,"TOTAL","") | H30: =IF(3=Header!B49,Header!B51,"")
A31: =IF(3=Header!B49,IF(Header!B3="COMMERCIAL",IF(Header!B43="","",Header!B43),IF(Header!B44="","",Header!B44)),"")
A33: =IF(3=Header!B49,"Authorized signatory","") | E33: =IF(3=Header!B49,"Signature / Date","")
A34: =IF(AND(3=Header!B49,Header!B41<>""),IF(Header!B41="","",Header!B41)&CHAR(10)&IF(Header!B42="","",Header!B42),"")
A37: =IF(3<=Header!B49,IF(Header!B4="","",Header!B4)&" • 3 / "&Header!B49,"")
